2025-02-28 19:24:12,431 - root - INFO - [Telegram Bot] 2025-02-28 19:24:12,431 - apscheduler.scheduler - INFO - Scheduler started
2025-02-28 19:24:12,433 - root - INFO - [Telegram Bot] 2025-02-28 19:24:12,431 - telegram.ext.Application - INFO - Application started
2025-02-28 19:24:12,522 - root - INFO - [Telegram Bot] 2025-02-28 19:24:12,522 - httpx - INFO - HTTP Request: POST https://api.telegram.org/bot8068331897:AAHa8V519tgNs7vFSEs9OdAyykx8yWH-Xx0/deleteWebhook "HTTP/1.1 200 OK"
2025-02-28 19:24:12,523 - root - INFO - [Telegram Bot] 2025-02-28 19:24:12,523 - __main__ - INFO - Telegram Bot started successfully.
2025-02-28 19:24:14,056 - root - INFO - [Flask App] Starting Flask application on port 10000...
2025-02-28 19:24:14,057 - root - INFO - [Flask App] * Serving Flask app 'app'
2025-02-28 19:24:14,058 - root - INFO - [Flask App] * Debug mode: on
2025-02-28 19:24:14,949 - root - INFO - [Flask App] 2025-02-28 19:24:14,949 - werkzeug - INFO - [31m[1mWARNING: This is a development server. Do not use it in a production deployment. Use a production WSGI server instead.[0m
2025-02-28 19:24:14,950 - root - INFO - [Flask App] * Running on all addresses (0.0.0.0)
2025-02-28 19:24:14,950 - root - INFO - [Flask App] * Running on http://127.0.0.1:10000
2025-02-28 19:24:14,950 - root - INFO - [Flask App] * Running on http://192.168.4.244:10000
2025-02-28 19:24:14,950 - root - INFO - [Flask App] 2025-02-28 19:24:14,949 - werkzeug - INFO - [33mPress CTRL+C to quit[0m
2025-02-28 19:24:14,954 - root - INFO - [Flask App] 2025-02-28 19:24:14,954 - werkzeug - INFO -  * Restarting with watchdog (windowsapi)
2025-02-28 19:24:15,632 - root - INFO - [Flask App] 2025-02-28 19:24:15,632 - app - INFO -  „ »œ¡  ‘€Ì·  ÿ»Ìﬁ MetaBit KYC
2025-02-28 19:24:15,632 - root - INFO - [Flask App] 2025-02-28 19:24:15,632 - app - INFO -  „ »œ¡  ‘€Ì·  ÿ»Ìﬁ MetaBit KYC
2025-02-28 19:24:17,208 - root - INFO - [Telegram Bot] 2025-02-28 19:24:17,208 - httpx - INFO - HTTP Request: POST https://api.telegram.org/bot8068331897:AAHa8V519tgNs7vFSEs9OdAyykx8yWH-Xx0/getUpdates "HTTP/1.1 409 Conflict"
2025-02-28 19:24:17,208 - root - INFO - [Telegram Bot] 2025-02-28 19:24:17,208 - telegram.ext.Updater - ERROR - Error while getting Updates: Conflict: terminated by other getUpdates request; make sure that only one bot instance is running
2025-02-28 19:24:17,211 - root - INFO - [Telegram Bot] 2025-02-28 19:24:17,208 - telegram.ext.Updater - ERROR - Exception happened while polling for updates.
2025-02-28 19:24:17,211 - root - INFO - [Telegram Bot] Traceback (most recent call last):
2025-02-28 19:24:17,211 - root - INFO - [Telegram Bot] File "C:\Python310\lib\site-packages\telegram\ext\_updater.py", line 688, in _network_loop_retry
2025-02-28 19:24:17,211 - root - INFO - [Telegram Bot] if not await action_cb():
2025-02-28 19:24:17,211 - root - INFO - [Telegram Bot] File "C:\Python310\lib\site-packages\telegram\ext\_updater.py", line 384, in polling_action_cb
2025-02-28 19:24:17,211 - root - INFO - [Telegram Bot] raise exc
2025-02-28 19:24:17,211 - root - INFO - [Telegram Bot] File "C:\Python310\lib\site-packages\telegram\ext\_updater.py", line 373, in polling_action_cb
2025-02-28 19:24:17,211 - root - INFO - [Telegram Bot] updates = await self.bot.get_updates(
2025-02-28 19:24:17,211 - root - INFO - [Telegram Bot] File "C:\Python310\lib\site-packages\telegram\ext\_extbot.py", line 558, in get_updates
2025-02-28 19:24:17,211 - root - INFO - [Telegram Bot] updates = await super().get_updates(
2025-02-28 19:24:17,211 - root - INFO - [Telegram Bot] File "C:\Python310\lib\site-packages\telegram\_bot.py", line 525, in decorator
2025-02-28 19:24:17,212 - root - INFO - [Telegram Bot] result = await func(self, *args, **kwargs)  # skipcq: PYL-E1102
2025-02-28 19:24:17,212 - root - INFO - [Telegram Bot] File "C:\Python310\lib\site-packages\telegram\_bot.py", line 3584, in get_updates
2025-02-28 19:24:17,212 - root - INFO - [Telegram Bot] await self._post(
2025-02-28 19:24:17,212 - root - INFO - [Telegram Bot] File "C:\Python310\lib\site-packages\telegram\_bot.py", line 613, in _post
2025-02-28 19:24:17,212 - root - INFO - [Telegram Bot] return await self._do_post(
2025-02-28 19:24:17,212 - root - INFO - [Telegram Bot] File "C:\Python310\lib\site-packages\telegram\ext\_extbot.py", line 340, in _do_post
2025-02-28 19:24:17,212 - root - INFO - [Telegram Bot] return await super()._do_post(
2025-02-28 19:24:17,212 - root - INFO - [Telegram Bot] File "C:\Python310\lib\site-packages\telegram\_bot.py", line 641, in _do_post
2025-02-28 19:24:17,212 - root - INFO - [Telegram Bot] return await request.post(
2025-02-28 19:24:17,212 - root - INFO - [Telegram Bot] File "C:\Python310\lib\site-packages\telegram\request\_baserequest.py", line 200, in post
2025-02-28 19:24:17,212 - root - INFO - [Telegram Bot] result = await self._request_wrapper(
2025-02-28 19:24:17,212 - root - INFO - [Telegram Bot] File "C:\Python310\lib\site-packages\telegram\request\_baserequest.py", line 381, in _request_wrapper
2025-02-28 19:24:17,214 - root - INFO - [Telegram Bot] raise Conflict(message)
2025-02-28 19:24:17,214 - root - INFO - [Telegram Bot] telegram.error.Conflict: Conflict: terminated by other getUpdates request; make sure that only one bot instance is running
2025-02-28 19:24:20,880 - root - INFO - [Flask App] 2025-02-28 19:24:20,880 - werkzeug - WARNING -  * Debugger is active!
2025-02-28 19:24:20,882 - root - INFO - [Flask App] 2025-02-28 19:24:20,882 - werkzeug - INFO -  * Debugger PIN: 535-157-907
2025-02-28 19:24:22,993 - root - INFO - [Telegram Bot] 2025-02-28 19:24:22,993 - httpx - INFO - HTTP Request: POST https://api.telegram.org/bot8068331897:AAHa8V519tgNs7vFSEs9OdAyykx8yWH-Xx0/getUpdates "HTTP/1.1 409 Conflict"
2025-02-28 19:24:22,994 - root - INFO - [Telegram Bot] 2025-02-28 19:24:22,994 - telegram.ext.Updater - ERROR - Error while getting Updates: Conflict: terminated by other getUpdates request; make sure that only one bot instance is running
2025-02-28 19:24:22,996 - root - INFO - [Telegram Bot] 2025-02-28 19:24:22,994 - telegram.ext.Updater - ERROR - Exception happened while polling for updates.
2025-02-28 19:24:22,996 - root - INFO - [Telegram Bot] Traceback (most recent call last):
2025-02-28 19:24:22,996 - root - INFO - [Telegram Bot] File "C:\Python310\lib\site-packages\telegram\ext\_updater.py", line 688, in _network_loop_retry
2025-02-28 19:24:22,996 - root - INFO - [Telegram Bot] if not await action_cb():
2025-02-28 19:24:22,996 - root - INFO - [Telegram Bot] File "C:\Python310\lib\site-packages\telegram\ext\_updater.py", line 384, in polling_action_cb
2025-02-28 19:24:22,996 - root - INFO - [Telegram Bot] raise exc
2025-02-28 19:24:22,996 - root - INFO - [Telegram Bot] File "C:\Python310\lib\site-packages\telegram\ext\_updater.py", line 373, in polling_action_cb
2025-02-28 19:24:22,997 - root - INFO - [Telegram Bot] updates = await self.bot.get_updates(
2025-02-28 19:24:22,997 - root - INFO - [Telegram Bot] File "C:\Python310\lib\site-packages\telegram\ext\_extbot.py", line 558, in get_updates
2025-02-28 19:24:22,997 - root - INFO - [Telegram Bot] updates = await super().get_updates(
2025-02-28 19:24:22,997 - root - INFO - [Telegram Bot] File "C:\Python310\lib\site-packages\telegram\_bot.py", line 525, in decorator
2025-02-28 19:24:22,997 - root - INFO - [Telegram Bot] result = await func(self, *args, **kwargs)  # skipcq: PYL-E1102
2025-02-28 19:24:22,998 - root - INFO - [Telegram Bot] File "C:\Python310\lib\site-packages\telegram\_bot.py", line 3584, in get_updates
2025-02-28 19:24:22,998 - root - INFO - [Telegram Bot] await self._post(
2025-02-28 19:24:22,998 - root - INFO - [Telegram Bot] File "C:\Python310\lib\site-packages\telegram\_bot.py", line 613, in _post
2025-02-28 19:24:22,998 - root - INFO - [Telegram Bot] return await self._do_post(
2025-02-28 19:24:22,998 - root - INFO - [Telegram Bot] File "C:\Python310\lib\site-packages\telegram\ext\_extbot.py", line 340, in _do_post
2025-02-28 19:24:22,998 - root - INFO - [Telegram Bot] return await super()._do_post(
2025-02-28 19:24:22,999 - root - INFO - [Telegram Bot] File "C:\Python310\lib\site-packages\telegram\_bot.py", line 641, in _do_post
2025-02-28 19:24:22,999 - root - INFO - [Telegram Bot] return await request.post(
2025-02-28 19:24:22,999 - root - INFO - [Telegram Bot] File "C:\Python310\lib\site-packages\telegram\request\_baserequest.py", line 200, in post
2025-02-28 19:24:22,999 - root - INFO - [Telegram Bot] result = await self._request_wrapper(
2025-02-28 19:24:22,999 - root - INFO - [Telegram Bot] File "C:\Python310\lib\site-packages\telegram\request\_baserequest.py", line 381, in _request_wrapper
2025-02-28 19:24:22,999 - root - INFO - [Telegram Bot] raise Conflict(message)
2025-02-28 19:24:22,999 - root - INFO - [Telegram Bot] telegram.error.Conflict: Conflict: terminated by other getUpdates request; make sure that only one bot instance is running
2025-02-28 19:24:27,787 - root - INFO - [Flask App] 2025-02-28 19:24:27,786 - werkzeug - INFO - 127.0.0.1 - - [28/Feb/2025 19:24:27] "GET / HTTP/1.1" 200 -
2025-02-28 19:24:27,848 - root - INFO - [Flask App] 2025-02-28 19:24:27,848 - werkzeug - INFO - 127.0.0.1 - - [28/Feb/2025 19:24:27] "GET /static/images/Logo.png HTTP/1.1" 200 -
2025-02-28 19:24:29,993 - root - INFO - [Flask App] 2025-02-28 19:24:29,993 - werkzeug - INFO - 127.0.0.1 - - [28/Feb/2025 19:24:29] "[33mGET /favicon.ico HTTP/1.1[0m" 404 -
2025-02-28 19:24:30,033 - root - INFO - [Telegram Bot] 2025-02-28 19:24:30,033 - httpx - INFO - HTTP Request: POST https://api.telegram.org/bot8068331897:AAHa8V519tgNs7vFSEs9OdAyykx8yWH-Xx0/getUpdates "HTTP/1.1 409 Conflict"
2025-02-28 19:24:30,034 - root - INFO - [Telegram Bot] 2025-02-28 19:24:30,034 - telegram.ext.Updater - ERROR - Error while getting Updates: Conflict: terminated by other getUpdates request; make sure that only one bot instance is running
2025-02-28 19:24:30,034 - root - INFO - [Telegram Bot] 2025-02-28 19:24:30,034 - telegram.ext.Updater - ERROR - Exception happened while polling for updates.
2025-02-28 19:24:30,035 - root - INFO - [Telegram Bot] Traceback (most recent call last):
