2025-02-28 19:25:27,991 - root - INFO - [Telegram Bot] return await super()._do_post(
2025-02-28 19:25:27,997 - root - INFO - [Telegram Bot] File "C:\Python310\lib\site-packages\telegram\_bot.py", line 641, in _do_post
2025-02-28 19:25:27,997 - root - INFO - [Telegram Bot] return await request.post(
2025-02-28 19:25:27,998 - root - INFO - [Telegram Bot] File "C:\Python310\lib\site-packages\telegram\request\_baserequest.py", line 200, in post
2025-02-28 19:25:27,998 - root - INFO - [Telegram Bot] result = await self._request_wrapper(
2025-02-28 19:25:27,998 - root - INFO - [Telegram Bot] File "C:\Python310\lib\site-packages\telegram\request\_baserequest.py", line 381, in _request_wrapper
2025-02-28 19:25:27,998 - root - INFO - [Telegram Bot] raise Conflict(message)
2025-02-28 19:25:28,000 - root - INFO - [Telegram Bot] telegram.error.Conflict: Conflict: terminated by other getUpdates request; make sure that only one bot instance is running
2025-02-28 19:25:33,749 - root - INFO - [Telegram Bot] 2025-02-28 19:25:33,748 - httpx - INFO - HTTP Request: POST https://api.telegram.org/bot8068331897:AAHa8V519tgNs7vFSEs9OdAyykx8yWH-Xx0/getUpdates "HTTP/1.1 409 Conflict"
2025-02-28 19:25:33,749 - root - INFO - [Telegram Bot] 2025-02-28 19:25:33,749 - telegram.ext.Updater - ERROR - Error while getting Updates: Conflict: terminated by other getUpdates request; make sure that only one bot instance is running
2025-02-28 19:25:33,749 - root - INFO - [Telegram Bot] 2025-02-28 19:25:33,749 - telegram.ext.Updater - ERROR - Exception happened while polling for updates.
2025-02-28 19:25:33,749 - root - INFO - [Telegram Bot] Traceback (most recent call last):
2025-02-28 19:25:33,750 - root - INFO - [Telegram Bot] File "C:\Python310\lib\site-packages\telegram\ext\_updater.py", line 688, in _network_loop_retry
2025-02-28 19:25:33,750 - root - INFO - [Telegram Bot] if not await action_cb():
2025-02-28 19:25:33,750 - root - INFO - [Telegram Bot] File "C:\Python310\lib\site-packages\telegram\ext\_updater.py", line 384, in polling_action_cb
2025-02-28 19:25:33,750 - root - INFO - [Telegram Bot] raise exc
2025-02-28 19:25:33,751 - root - INFO - [Telegram Bot] File "C:\Python310\lib\site-packages\telegram\ext\_updater.py", line 373, in polling_action_cb
2025-02-28 19:25:33,751 - root - INFO - [Telegram Bot] updates = await self.bot.get_updates(
2025-02-28 19:25:33,751 - root - INFO - [Telegram Bot] File "C:\Python310\lib\site-packages\telegram\ext\_extbot.py", line 558, in get_updates
2025-02-28 19:25:33,751 - root - INFO - [Telegram Bot] updates = await super().get_updates(
2025-02-28 19:25:33,751 - root - INFO - [Telegram Bot] File "C:\Python310\lib\site-packages\telegram\_bot.py", line 525, in decorator
2025-02-28 19:25:33,752 - root - INFO - [Telegram Bot] result = await func(self, *args, **kwargs)  # skipcq: PYL-E1102
2025-02-28 19:25:33,752 - root - INFO - [Telegram Bot] File "C:\Python310\lib\site-packages\telegram\_bot.py", line 3584, in get_updates
2025-02-28 19:25:33,752 - root - INFO - [Telegram Bot] await self._post(
2025-02-28 19:25:33,752 - root - INFO - [Telegram Bot] File "C:\Python310\lib\site-packages\telegram\_bot.py", line 613, in _post
2025-02-28 19:25:33,752 - root - INFO - [Telegram Bot] return await self._do_post(
2025-02-28 19:25:33,752 - root - INFO - [Telegram Bot] File "C:\Python310\lib\site-packages\telegram\ext\_extbot.py", line 340, in _do_post
2025-02-28 19:25:33,752 - root - INFO - [Telegram Bot] return await super()._do_post(
2025-02-28 19:25:33,752 - root - INFO - [Telegram Bot] File "C:\Python310\lib\site-packages\telegram\_bot.py", line 641, in _do_post
2025-02-28 19:25:33,752 - root - INFO - [Telegram Bot] return await request.post(
2025-02-28 19:25:33,753 - root - INFO - [Telegram Bot] File "C:\Python310\lib\site-packages\telegram\request\_baserequest.py", line 200, in post
2025-02-28 19:25:33,753 - root - INFO - [Telegram Bot] result = await self._request_wrapper(
2025-02-28 19:25:33,753 - root - INFO - [Telegram Bot] File "C:\Python310\lib\site-packages\telegram\request\_baserequest.py", line 381, in _request_wrapper
2025-02-28 19:25:33,753 - root - INFO - [Telegram Bot] raise Conflict(message)
2025-02-28 19:25:33,753 - root - INFO - [Telegram Bot] telegram.error.Conflict: Conflict: terminated by other getUpdates request; make sure that only one bot instance is running
2025-02-28 19:25:40,761 - root - INFO - [Telegram Bot] 2025-02-28 19:25:40,761 - httpx - INFO - HTTP Request: POST https://api.telegram.org/bot8068331897:AAHa8V519tgNs7vFSEs9OdAyykx8yWH-Xx0/getUpdates "HTTP/1.1 409 Conflict"
2025-02-28 19:25:40,761 - root - INFO - [Telegram Bot] 2025-02-28 19:25:40,761 - telegram.ext.Updater - ERROR - Error while getting Updates: Conflict: terminated by other getUpdates request; make sure that only one bot instance is running
2025-02-28 19:25:40,762 - root - INFO - [Telegram Bot] 2025-02-28 19:25:40,761 - telegram.ext.Updater - ERROR - Exception happened while polling for updates.
2025-02-28 19:25:40,762 - root - INFO - [Telegram Bot] Traceback (most recent call last):
2025-02-28 19:25:40,762 - root - INFO - [Telegram Bot] File "C:\Python310\lib\site-packages\telegram\ext\_updater.py", line 688, in _network_loop_retry
2025-02-28 19:25:40,762 - root - INFO - [Telegram Bot] if not await action_cb():
2025-02-28 19:25:40,762 - root - INFO - [Telegram Bot] File "C:\Python310\lib\site-packages\telegram\ext\_updater.py", line 384, in polling_action_cb
2025-02-28 19:25:40,763 - root - INFO - [Telegram Bot] raise exc
2025-02-28 19:25:40,763 - root - INFO - [Telegram Bot] File "C:\Python310\lib\site-packages\telegram\ext\_updater.py", line 373, in polling_action_cb
2025-02-28 19:25:40,763 - root - INFO - [Telegram Bot] updates = await self.bot.get_updates(
2025-02-28 19:25:40,763 - root - INFO - [Telegram Bot] File "C:\Python310\lib\site-packages\telegram\ext\_extbot.py", line 558, in get_updates
2025-02-28 19:25:40,763 - root - INFO - [Telegram Bot] updates = await super().get_updates(
2025-02-28 19:25:40,763 - root - INFO - [Telegram Bot] File "C:\Python310\lib\site-packages\telegram\_bot.py", line 525, in decorator
2025-02-28 19:25:40,763 - root - INFO - [Telegram Bot] result = await func(self, *args, **kwargs)  # skipcq: PYL-E1102
2025-02-28 19:25:40,763 - root - INFO - [Telegram Bot] File "C:\Python310\lib\site-packages\telegram\_bot.py", line 3584, in get_updates
2025-02-28 19:25:40,763 - root - INFO - [Telegram Bot] await self._post(
2025-02-28 19:25:40,763 - root - INFO - [Telegram Bot] File "C:\Python310\lib\site-packages\telegram\_bot.py", line 613, in _post
2025-02-28 19:25:40,764 - root - INFO - [Telegram Bot] return await self._do_post(
2025-02-28 19:25:40,764 - root - INFO - [Telegram Bot] File "C:\Python310\lib\site-packages\telegram\ext\_extbot.py", line 340, in _do_post
2025-02-28 19:25:40,764 - root - INFO - [Telegram Bot] return await super()._do_post(
2025-02-28 19:25:40,764 - root - INFO - [Telegram Bot] File "C:\Python310\lib\site-packages\telegram\_bot.py", line 641, in _do_post
2025-02-28 19:25:40,764 - root - INFO - [Telegram Bot] return await request.post(
2025-02-28 19:25:40,764 - root - INFO - [Telegram Bot] File "C:\Python310\lib\site-packages\telegram\request\_baserequest.py", line 200, in post
2025-02-28 19:25:40,764 - root - INFO - [Telegram Bot] result = await self._request_wrapper(
2025-02-28 19:25:40,764 - root - INFO - [Telegram Bot] File "C:\Python310\lib\site-packages\telegram\request\_baserequest.py", line 381, in _request_wrapper
2025-02-28 19:25:40,764 - root - INFO - [Telegram Bot] raise Conflict(message)
2025-02-28 19:25:40,764 - root - INFO - [Telegram Bot] telegram.error.Conflict: Conflict: terminated by other getUpdates request; make sure that only one bot instance is running
2025-02-28 19:25:46,046 - root - INFO - [Flask App] Exception ignored in: <function _ProactorBasePipeTransport.__del__ at 0x000001D54077E8C0>
2025-02-28 19:25:46,046 - root - INFO - [Flask App] Traceback (most recent call last):
2025-02-28 19:25:46,046 - root - INFO - [Flask App] File "C:\Python310\lib\asyncio\proactor_events.py", line 116, in __del__
2025-02-28 19:25:46,053 - root - INFO - [Flask App] self.close()
2025-02-28 19:25:46,053 - root - INFO - [Flask App] File "C:\Python310\lib\asyncio\proactor_events.py", line 108, in close
2025-02-28 19:25:46,054 - root - INFO - [Flask App] 2025-02-28 19:25:46,053 - werkzeug - INFO -  * Detected change in 'C:\\Python310\\Lib\\asyncio\\proactor_events.py', reloading
2025-02-28 19:25:46,054 - root - INFO - [Flask App] self._loop.call_soon(self._call_connection_lost, None)
2025-02-28 19:25:46,054 - root - INFO - [Flask App] File "C:\Python310\lib\asyncio\base_events.py", line 745, in call_soon
2025-02-28 19:25:46,054 - root - INFO - [Flask App] self._check_closed()
2025-02-28 19:25:46,054 - root - INFO - [Flask App] File "C:\Python310\lib\asyncio\base_events.py", line 510, in _check_closed
2025-02-28 19:25:46,054 - root - INFO - [Flask App] raise RuntimeError('Event loop is closed')
2025-02-28 19:25:46,054 - root - INFO - [Flask App] RuntimeError: Event loop is closed
2025-02-28 19:25:46,433 - root - INFO - [Flask App] Exception in thread Thread-2 (serve_forever):
2025-02-28 19:25:46,434 - root - INFO - [Flask App] Traceback (most recent call last):
2025-02-28 19:25:46,435 - root - INFO - [Flask App] File "C:\Python310\lib\threading.py", line 1009, in _bootstrap_inner
2025-02-28 19:25:46,541 - root - INFO - [Flask App] 2025-02-28 19:25:46,540 - werkzeug - INFO -  * Restarting with watchdog (windowsapi)
2025-02-28 19:25:46,706 - root - INFO - [Telegram Bot] 2025-02-28 19:25:46,706 - httpx - INFO - HTTP Request: POST https://api.telegram.org/bot8068331897:AAHa8V519tgNs7vFSEs9OdAyykx8yWH-Xx0/getUpdates "HTTP/1.1 409 Conflict"
2025-02-28 19:25:46,707 - root - INFO - [Telegram Bot] 2025-02-28 19:25:46,707 - telegram.ext.Updater - ERROR - Error while getting Updates: Conflict: terminated by other getUpdates request; make sure that only one bot instance is running
