2025-02-28 19:13:51,699 - root - INFO - [Telegram Bot] result = await func(self, *args, **kwargs)  # skipcq: PYL-E1102
2025-02-28 19:13:51,715 - root - INFO - [Telegram Bot] File "C:\Python310\lib\site-packages\telegram\_bot.py", line 3584, in get_updates
2025-02-28 19:13:51,715 - root - INFO - [Telegram Bot] await self._post(
2025-02-28 19:13:51,716 - root - INFO - [Telegram Bot] File "C:\Python310\lib\site-packages\telegram\_bot.py", line 613, in _post
2025-02-28 19:13:51,716 - root - INFO - [Telegram Bot] return await self._do_post(
2025-02-28 19:13:51,716 - root - INFO - [Telegram Bot] File "C:\Python310\lib\site-packages\telegram\ext\_extbot.py", line 340, in _do_post
2025-02-28 19:13:51,716 - root - INFO - [Telegram Bot] return await super()._do_post(
2025-02-28 19:13:51,718 - root - INFO - [Telegram Bot] File "C:\Python310\lib\site-packages\telegram\_bot.py", line 641, in _do_post
2025-02-28 19:13:51,718 - root - INFO - [Telegram Bot] return await request.post(
2025-02-28 19:13:51,718 - root - INFO - [Telegram Bot] File "C:\Python310\lib\site-packages\telegram\request\_baserequest.py", line 200, in post
2025-02-28 19:13:51,719 - root - INFO - [Telegram Bot] result = await self._request_wrapper(
2025-02-28 19:13:51,719 - root - INFO - [Telegram Bot] File "C:\Python310\lib\site-packages\telegram\request\_baserequest.py", line 381, in _request_wrapper
2025-02-28 19:13:51,719 - root - INFO - [Telegram Bot] raise Conflict(message)
2025-02-28 19:13:51,719 - root - INFO - [Telegram Bot] telegram.error.Conflict: Conflict: terminated by other getUpdates request; make sure that only one bot instance is running
2025-02-28 19:14:02,789 - root - INFO - [Telegram Bot] 2025-02-28 19:14:02,788 - httpx - INFO - HTTP Request: POST https://api.telegram.org/bot8068331897:AAHa8V519tgNs7vFSEs9OdAyykx8yWH-Xx0/getUpdates "HTTP/1.1 200 OK"
2025-02-28 19:14:12,903 - root - INFO - [Telegram Bot] 2025-02-28 19:14:12,902 - httpx - INFO - HTTP Request: POST https://api.telegram.org/bot8068331897:AAHa8V519tgNs7vFSEs9OdAyykx8yWH-Xx0/getUpdates "HTTP/1.1 200 OK"
2025-02-28 19:14:23,026 - root - INFO - [Telegram Bot] 2025-02-28 19:14:23,026 - httpx - INFO - HTTP Request: POST https://api.telegram.org/bot8068331897:AAHa8V519tgNs7vFSEs9OdAyykx8yWH-Xx0/getUpdates "HTTP/1.1 200 OK"
2025-02-28 19:14:26,286 - root - INFO - [Telegram Bot] 2025-02-28 19:14:26,286 - httpx - INFO - HTTP Request: POST https://api.telegram.org/bot8068331897:AAHa8V519tgNs7vFSEs9OdAyykx8yWH-Xx0/getUpdates "HTTP/1.1 409 Conflict"
2025-02-28 19:14:26,286 - root - INFO - [Telegram Bot] 2025-02-28 19:14:26,286 - telegram.ext.Updater - ERROR - Error while getting Updates: Conflict: terminated by other getUpdates request; make sure that only one bot instance is running
2025-02-28 19:14:26,287 - root - INFO - [Telegram Bot] 2025-02-28 19:14:26,286 - telegram.ext.Updater - ERROR - Exception happened while polling for updates.
2025-02-28 19:14:26,287 - root - INFO - [Telegram Bot] Traceback (most recent call last):
2025-02-28 19:14:26,287 - root - INFO - [Telegram Bot] File "C:\Python310\lib\site-packages\telegram\ext\_updater.py", line 688, in _network_loop_retry
2025-02-28 19:14:26,287 - root - INFO - [Telegram Bot] if not await action_cb():
2025-02-28 19:14:26,287 - root - INFO - [Telegram Bot] File "C:\Python310\lib\site-packages\telegram\ext\_updater.py", line 384, in polling_action_cb
2025-02-28 19:14:26,288 - root - INFO - [Telegram Bot] raise exc
2025-02-28 19:14:26,288 - root - INFO - [Telegram Bot] File "C:\Python310\lib\site-packages\telegram\ext\_updater.py", line 373, in polling_action_cb
2025-02-28 19:14:26,288 - root - INFO - [Telegram Bot] updates = await self.bot.get_updates(
2025-02-28 19:14:26,288 - root - INFO - [Telegram Bot] File "C:\Python310\lib\site-packages\telegram\ext\_extbot.py", line 558, in get_updates
2025-02-28 19:14:26,288 - root - INFO - [Telegram Bot] updates = await super().get_updates(
2025-02-28 19:14:26,288 - root - INFO - [Telegram Bot] File "C:\Python310\lib\site-packages\telegram\_bot.py", line 525, in decorator
2025-02-28 19:14:26,289 - root - INFO - [Telegram Bot] result = await func(self, *args, **kwargs)  # skipcq: PYL-E1102
2025-02-28 19:14:26,289 - root - INFO - [Telegram Bot] File "C:\Python310\lib\site-packages\telegram\_bot.py", line 3584, in get_updates
2025-02-28 19:14:26,289 - root - INFO - [Telegram Bot] await self._post(
2025-02-28 19:14:26,289 - root - INFO - [Telegram Bot] File "C:\Python310\lib\site-packages\telegram\_bot.py", line 613, in _post
2025-02-28 19:14:26,289 - root - INFO - [Telegram Bot] return await self._do_post(
2025-02-28 19:14:26,290 - root - INFO - [Telegram Bot] File "C:\Python310\lib\site-packages\telegram\ext\_extbot.py", line 340, in _do_post
2025-02-28 19:14:26,290 - root - INFO - [Telegram Bot] return await super()._do_post(
2025-02-28 19:14:26,290 - root - INFO - [Telegram Bot] File "C:\Python310\lib\site-packages\telegram\_bot.py", line 641, in _do_post
2025-02-28 19:14:26,290 - root - INFO - [Telegram Bot] return await request.post(
2025-02-28 19:14:26,290 - root - INFO - [Telegram Bot] File "C:\Python310\lib\site-packages\telegram\request\_baserequest.py", line 200, in post
2025-02-28 19:14:26,290 - root - INFO - [Telegram Bot] result = await self._request_wrapper(
2025-02-28 19:14:26,290 - root - INFO - [Telegram Bot] File "C:\Python310\lib\site-packages\telegram\request\_baserequest.py", line 381, in _request_wrapper
2025-02-28 19:14:26,290 - root - INFO - [Telegram Bot] raise Conflict(message)
2025-02-28 19:14:26,291 - root - INFO - [Telegram Bot] telegram.error.Conflict: Conflict: terminated by other getUpdates request; make sure that only one bot instance is running
2025-02-28 19:14:37,394 - root - INFO - [Telegram Bot] 2025-02-28 19:14:37,394 - httpx - INFO - HTTP Request: POST https://api.telegram.org/bot8068331897:AAHa8V519tgNs7vFSEs9OdAyykx8yWH-Xx0/getUpdates "HTTP/1.1 200 OK"
2025-02-28 19:14:47,488 - root - INFO - [Telegram Bot] 2025-02-28 19:14:47,487 - httpx - INFO - HTTP Request: POST https://api.telegram.org/bot8068331897:AAHa8V519tgNs7vFSEs9OdAyykx8yWH-Xx0/getUpdates "HTTP/1.1 200 OK"
2025-02-28 19:14:57,571 - root - INFO - [Telegram Bot] 2025-02-28 19:14:57,571 - httpx - INFO - HTTP Request: POST https://api.telegram.org/bot8068331897:AAHa8V519tgNs7vFSEs9OdAyykx8yWH-Xx0/getUpdates "HTTP/1.1 200 OK"
2025-02-28 19:15:00,891 - root - INFO - [Telegram Bot] 2025-02-28 19:15:00,891 - httpx - INFO - HTTP Request: POST https://api.telegram.org/bot8068331897:AAHa8V519tgNs7vFSEs9OdAyykx8yWH-Xx0/getUpdates "HTTP/1.1 409 Conflict"
2025-02-28 19:15:00,892 - root - INFO - [Telegram Bot] 2025-02-28 19:15:00,891 - telegram.ext.Updater - ERROR - Error while getting Updates: Conflict: terminated by other getUpdates request; make sure that only one bot instance is running
2025-02-28 19:15:00,892 - root - INFO - [Telegram Bot] 2025-02-28 19:15:00,891 - telegram.ext.Updater - ERROR - Exception happened while polling for updates.
2025-02-28 19:15:00,892 - root - INFO - [Telegram Bot] Traceback (most recent call last):
2025-02-28 19:15:00,892 - root - INFO - [Telegram Bot] File "C:\Python310\lib\site-packages\telegram\ext\_updater.py", line 688, in _network_loop_retry
2025-02-28 19:15:00,892 - root - INFO - [Telegram Bot] if not await action_cb():
2025-02-28 19:15:00,892 - root - INFO - [Telegram Bot] File "C:\Python310\lib\site-packages\telegram\ext\_updater.py", line 384, in polling_action_cb
2025-02-28 19:15:00,892 - root - INFO - [Telegram Bot] raise exc
2025-02-28 19:15:00,892 - root - INFO - [Telegram Bot] File "C:\Python310\lib\site-packages\telegram\ext\_updater.py", line 373, in polling_action_cb
2025-02-28 19:15:00,894 - root - INFO - [Telegram Bot] updates = await self.bot.get_updates(
2025-02-28 19:15:00,894 - root - INFO - [Telegram Bot] File "C:\Python310\lib\site-packages\telegram\ext\_extbot.py", line 558, in get_updates
2025-02-28 19:15:00,894 - root - INFO - [Telegram Bot] updates = await super().get_updates(
2025-02-28 19:15:00,894 - root - INFO - [Telegram Bot] File "C:\Python310\lib\site-packages\telegram\_bot.py", line 525, in decorator
2025-02-28 19:15:00,894 - root - INFO - [Telegram Bot] result = await func(self, *args, **kwargs)  # skipcq: PYL-E1102
2025-02-28 19:15:00,894 - root - INFO - [Telegram Bot] File "C:\Python310\lib\site-packages\telegram\_bot.py", line 3584, in get_updates
2025-02-28 19:15:00,894 - root - INFO - [Telegram Bot] await self._post(
2025-02-28 19:15:00,894 - root - INFO - [Telegram Bot] File "C:\Python310\lib\site-packages\telegram\_bot.py", line 613, in _post
2025-02-28 19:15:00,894 - root - INFO - [Telegram Bot] return await self._do_post(
2025-02-28 19:15:00,895 - root - INFO - [Telegram Bot] File "C:\Python310\lib\site-packages\telegram\ext\_extbot.py", line 340, in _do_post
2025-02-28 19:15:00,895 - root - INFO - [Telegram Bot] return await super()._do_post(
2025-02-28 19:15:00,895 - root - INFO - [Telegram Bot] File "C:\Python310\lib\site-packages\telegram\_bot.py", line 641, in _do_post
2025-02-28 19:15:00,895 - root - INFO - [Telegram Bot] return await request.post(
2025-02-28 19:15:00,895 - root - INFO - [Telegram Bot] File "C:\Python310\lib\site-packages\telegram\request\_baserequest.py", line 200, in post
2025-02-28 19:15:00,896 - root - INFO - [Telegram Bot] result = await self._request_wrapper(
2025-02-28 19:15:00,896 - root - INFO - [Telegram Bot] File "C:\Python310\lib\site-packages\telegram\request\_baserequest.py", line 381, in _request_wrapper
2025-02-28 19:15:00,896 - root - INFO - [Telegram Bot] raise Conflict(message)
2025-02-28 19:15:00,896 - root - INFO - [Telegram Bot] telegram.error.Conflict: Conflict: terminated by other getUpdates request; make sure that only one bot instance is running
2025-02-28 19:15:11,994 - root - INFO - [Telegram Bot] 2025-02-28 19:15:11,994 - httpx - INFO - HTTP Request: POST https://api.telegram.org/bot8068331897:AAHa8V519tgNs7vFSEs9OdAyykx8yWH-Xx0/getUpdates "HTTP/1.1 200 OK"
