2025-02-28 19:15:22,085 - root - INFO - [Telegram Bot] 2025-02-28 19:15:22,085 - httpx - INFO - HTTP Request: POST https://api.telegram.org/bot8068331897:AAHa8V519tgNs7vFSEs9OdAyykx8yWH-Xx0/getUpdates "HTTP/1.1 200 OK"
2025-02-28 19:15:32,179 - root - INFO - [Telegram Bot] 2025-02-28 19:15:32,179 - httpx - INFO - HTTP Request: POST https://api.telegram.org/bot8068331897:AAHa8V519tgNs7vFSEs9OdAyykx8yWH-Xx0/getUpdates "HTTP/1.1 200 OK"
2025-02-28 19:15:35,532 - root - INFO - [Telegram Bot] 2025-02-28 19:15:35,531 - httpx - INFO - HTTP Request: POST https://api.telegram.org/bot8068331897:AAHa8V519tgNs7vFSEs9OdAyykx8yWH-Xx0/getUpdates "HTTP/1.1 409 Conflict"
2025-02-28 19:15:35,534 - root - INFO - [Telegram Bot] 2025-02-28 19:15:35,533 - telegram.ext.Updater - ERROR - Error while getting Updates: Conflict: terminated by other getUpdates request; make sure that only one bot instance is running
2025-02-28 19:15:35,537 - root - INFO - [Telegram Bot] 2025-02-28 19:15:35,534 - telegram.ext.Updater - ERROR - Exception happened while polling for updates.
2025-02-28 19:15:35,537 - root - INFO - [Telegram Bot] Traceback (most recent call last):
2025-02-28 19:15:35,538 - root - INFO - [Telegram Bot] File "C:\Python310\lib\site-packages\telegram\ext\_updater.py", line 688, in _network_loop_retry
2025-02-28 19:15:35,538 - root - INFO - [Telegram Bot] if not await action_cb():
2025-02-28 19:15:35,538 - root - INFO - [Telegram Bot] File "C:\Python310\lib\site-packages\telegram\ext\_updater.py", line 384, in polling_action_cb
2025-02-28 19:15:35,538 - root - INFO - [Telegram Bot] raise exc
2025-02-28 19:15:35,538 - root - INFO - [Telegram Bot] File "C:\Python310\lib\site-packages\telegram\ext\_updater.py", line 373, in polling_action_cb
2025-02-28 19:15:35,539 - root - INFO - [Telegram Bot] updates = await self.bot.get_updates(
2025-02-28 19:15:35,539 - root - INFO - [Telegram Bot] File "C:\Python310\lib\site-packages\telegram\ext\_extbot.py", line 558, in get_updates
2025-02-28 19:15:35,539 - root - INFO - [Telegram Bot] updates = await super().get_updates(
2025-02-28 19:15:35,539 - root - INFO - [Telegram Bot] File "C:\Python310\lib\site-packages\telegram\_bot.py", line 525, in decorator
2025-02-28 19:15:35,540 - root - INFO - [Telegram Bot] result = await func(self, *args, **kwargs)  # skipcq: PYL-E1102
2025-02-28 19:15:35,540 - root - INFO - [Telegram Bot] File "C:\Python310\lib\site-packages\telegram\_bot.py", line 3584, in get_updates
2025-02-28 19:15:35,540 - root - INFO - [Telegram Bot] await self._post(
2025-02-28 19:15:35,540 - root - INFO - [Telegram Bot] File "C:\Python310\lib\site-packages\telegram\_bot.py", line 613, in _post
2025-02-28 19:15:35,540 - root - INFO - [Telegram Bot] return await self._do_post(
2025-02-28 19:15:35,541 - root - INFO - [Telegram Bot] File "C:\Python310\lib\site-packages\telegram\ext\_extbot.py", line 340, in _do_post
2025-02-28 19:15:35,541 - root - INFO - [Telegram Bot] return await super()._do_post(
2025-02-28 19:15:35,541 - root - INFO - [Telegram Bot] File "C:\Python310\lib\site-packages\telegram\_bot.py", line 641, in _do_post
2025-02-28 19:15:35,541 - root - INFO - [Telegram Bot] return await request.post(
2025-02-28 19:15:35,541 - root - INFO - [Telegram Bot] File "C:\Python310\lib\site-packages\telegram\request\_baserequest.py", line 200, in post
2025-02-28 19:15:35,542 - root - INFO - [Telegram Bot] result = await self._request_wrapper(
2025-02-28 19:15:35,542 - root - INFO - [Telegram Bot] File "C:\Python310\lib\site-packages\telegram\request\_baserequest.py", line 381, in _request_wrapper
2025-02-28 19:15:35,543 - root - INFO - [Telegram Bot] raise Conflict(message)
2025-02-28 19:15:35,543 - root - INFO - [Telegram Bot] telegram.error.Conflict: Conflict: terminated by other getUpdates request; make sure that only one bot instance is running
2025-02-28 19:15:44,434 - root - INFO - === Starting MetaBit KYC System ===
2025-02-28 19:15:44,435 - root - INFO - Starting Flask App...
2025-02-28 19:15:45,220 - root - INFO - [Flask App] 2025-02-28 19:15:45,220 - app - INFO -  „ »œ¡  ‘€Ì·  ÿ»Ìﬁ MetaBit KYC
2025-02-28 19:15:45,221 - root - INFO - [Flask App] 2025-02-28 19:15:45,220 - app - INFO -  „ »œ¡  ‘€Ì·  ÿ»Ìﬁ MetaBit KYC
2025-02-28 19:15:46,435 - root - INFO - Starting Telegram Bot...
2025-02-28 19:15:46,648 - root - INFO - [Telegram Bot] 2025-02-28 19:15:46,648 - httpx - INFO - HTTP Request: POST https://api.telegram.org/bot8068331897:AAHa8V519tgNs7vFSEs9OdAyykx8yWH-Xx0/getUpdates "HTTP/1.1 200 OK"
2025-02-28 19:15:47,162 - root - INFO - [Telegram Bot] 2025-02-28 19:15:47,162 - __main__ - INFO - Bot Token: 80683...
2025-02-28 19:15:47,162 - root - INFO - [Telegram Bot] 2025-02-28 19:15:47,162 - __main__ - INFO - Admin Group ID: -1002484172002
2025-02-28 19:15:51,076 - root - INFO - [Telegram Bot] INFO:     Started server process [22212]
2025-02-28 19:15:51,076 - root - INFO - [Telegram Bot] INFO:     Waiting for application startup.
2025-02-28 19:15:51,076 - root - INFO - [Telegram Bot] INFO:     Application startup complete.
2025-02-28 19:15:51,079 - root - INFO - [Telegram Bot] ERROR:    [Errno 10048] error while attempting to bind on address ('0.0.0.0', 8888): only one usage of each socket address (protocol/network address/port) is normally permitted
2025-02-28 19:15:51,079 - root - INFO - [Telegram Bot] INFO:     Waiting for application shutdown.
2025-02-28 19:15:51,079 - root - INFO - [Telegram Bot] INFO:     Application shutdown complete.
2025-02-28 19:15:51,079 - root - INFO - [Telegram Bot] Starting MetaBit KYC Verification System...
2025-02-28 19:15:51,080 - root - INFO - [Telegram Bot] Telegram Bot Token: 80683...
2025-02-28 19:15:51,080 - root - INFO - [Telegram Bot] Admin Group ID: -1002484172002
2025-02-28 19:15:51,080 - root - INFO - [Telegram Bot] Starting bot and FastAPI server...
2025-02-28 19:15:51,080 - root - INFO - [Telegram Bot] Warning: Database connection failed. Check your database settings.
2025-02-28 19:15:51,080 - root - INFO - [Telegram Bot] Application shutdown complete.
2025-02-28 19:15:51,189 - root - INFO - [Flask App] 2025-02-28 19:15:51,188 - werkzeug - INFO -  * Detected change in 'C:\\Python310\\Lib\\asyncio\\runners.py', reloading
2025-02-28 19:15:51,212 - root - INFO - [Flask App] 2025-02-28 19:15:51,212 - werkzeug - INFO -  * Detected change in 'C:\\Python310\\Lib\\asyncio\\base_events.py', reloading
2025-02-28 19:15:51,218 - root - INFO - [Flask App] 2025-02-28 19:15:51,218 - werkzeug - INFO -  * Detected change in 'C:\\Python310\\Lib\\asyncio\\windows_events.py', reloading
2025-02-28 19:15:51,225 - root - INFO - [Flask App] 2025-02-28 19:15:51,224 - werkzeug - INFO -  * Detected change in 'C:\\Python310\\Lib\\asyncio\\events.py', reloading
2025-02-28 19:15:51,228 - root - INFO - [Telegram Bot] 2025-02-28 19:15:51,179 - asyncio - ERROR - Task exception was never retrieved
2025-02-28 19:15:51,228 - root - INFO - [Telegram Bot] future: <Task finished name='Task-4' coro=<main() done, defined at C:\Users\PC\CascadeProjects\kyc-web-app\main.py:1011> exception=SystemExit(1)>
2025-02-28 19:15:51,228 - root - INFO - [Flask App] 2025-02-28 19:15:51,228 - werkzeug - INFO -  * Detected change in 'C:\\Python310\\Lib\\site-packages\\uvicorn\\server.py', reloading
2025-02-28 19:15:51,228 - root - INFO - [Telegram Bot] Traceback (most recent call last):
2025-02-28 19:15:51,228 - root - INFO - [Telegram Bot] File "C:\Python310\lib\site-packages\uvicorn\server.py", line 160, in startup
2025-02-28 19:15:51,228 - root - INFO - [Telegram Bot] server = await loop.create_server(
2025-02-28 19:15:51,230 - root - INFO - [Telegram Bot] File "C:\Python310\lib\asyncio\base_events.py", line 1493, in create_server
2025-02-28 19:15:51,230 - root - INFO - [Telegram Bot] raise OSError(err.errno, 'error while attempting '
2025-02-28 19:15:51,230 - root - INFO - [Telegram Bot] OSError: [Errno 10048] error while attempting to bind on address ('0.0.0.0', 8888): only one usage of each socket address (protocol/network address/port) is normally permitted
2025-02-28 19:15:51,230 - root - INFO - [Telegram Bot] During handling of the above exception, another exception occurred:
2025-02-28 19:15:51,230 - root - INFO - [Telegram Bot] Traceback (most recent call last):
2025-02-28 19:15:51,230 - root - INFO - [Telegram Bot] File "C:\Users\PC\CascadeProjects\kyc-web-app\main.py", line 1120, in <module>
2025-02-28 19:15:51,230 - root - INFO - [Telegram Bot] asyncio.run(main())
2025-02-28 19:15:51,231 - root - INFO - [Telegram Bot] File "C:\Python310\lib\asyncio\runners.py", line 47, in run
2025-02-28 19:15:51,231 - root - INFO - [Telegram Bot] _cancel_all_tasks(loop)
2025-02-28 19:15:51,231 - root - INFO - [Telegram Bot] File "C:\Python310\lib\asyncio\runners.py", line 63, in _cancel_all_tasks
2025-02-28 19:15:51,231 - root - INFO - [Telegram Bot] loop.run_until_complete(tasks.gather(*to_cancel, return_exceptions=True))
2025-02-28 19:15:51,231 - root - INFO - [Telegram Bot] File "C:\Python310\lib\asyncio\base_events.py", line 628, in run_until_complete
2025-02-28 19:15:51,231 - root - INFO - [Telegram Bot] self.run_forever()
2025-02-28 19:15:51,231 - root - INFO - [Telegram Bot] File "C:\Python310\lib\asyncio\windows_events.py", line 316, in run_forever
2025-02-28 19:15:51,231 - root - INFO - [Telegram Bot] super().run_forever()
2025-02-28 19:15:51,232 - root - INFO - [Telegram Bot] File "C:\Python310\lib\asyncio\base_events.py", line 595, in run_forever
2025-02-28 19:15:51,232 - root - INFO - [Telegram Bot] self._run_once()
2025-02-28 19:15:51,232 - root - INFO - [Telegram Bot] File "C:\Python310\lib\asyncio\base_events.py", line 1881, in _run_once
2025-02-28 19:15:51,232 - root - INFO - [Telegram Bot] handle._run()
2025-02-28 19:15:51,232 - root - INFO - [Telegram Bot] File "C:\Python310\lib\asyncio\events.py", line 80, in _run
2025-02-28 19:15:51,232 - root - INFO - [Telegram Bot] self._context.run(self._callback, *self._args)
2025-02-28 19:15:51,232 - root - INFO - [Telegram Bot] File "C:\Users\PC\CascadeProjects\kyc-web-app\main.py", line 1013, in main
2025-02-28 19:15:51,232 - root - INFO - [Telegram Bot] await asyncio.gather(
