2025-02-28 19:12:39,075 - root - INFO - [Telegram Bot] 2025-02-28 19:12:39,075 - httpx - INFO - HTTP Request: POST https://api.telegram.org/bot8068331897:AAHa8V519tgNs7vFSEs9OdAyykx8yWH-Xx0/getUpdates "HTTP/1.1 200 OK"
2025-02-28 19:12:42,372 - root - INFO - [Telegram Bot] 2025-02-28 19:12:42,371 - httpx - INFO - HTTP Request: POST https://api.telegram.org/bot8068331897:AAHa8V519tgNs7vFSEs9OdAyykx8yWH-Xx0/getUpdates "HTTP/1.1 409 Conflict"
2025-02-28 19:12:42,372 - root - INFO - [Telegram Bot] 2025-02-28 19:12:42,372 - telegram.ext.Updater - ERROR - Error while getting Updates: Conflict: terminated by other getUpdates request; make sure that only one bot instance is running
2025-02-28 19:12:42,373 - root - INFO - [Telegram Bot] 2025-02-28 19:12:42,372 - telegram.ext.Updater - ERROR - Exception happened while polling for updates.
2025-02-28 19:12:42,375 - root - INFO - [Telegram Bot] Traceback (most recent call last):
2025-02-28 19:12:42,375 - root - INFO - [Telegram Bot] File "C:\Python310\lib\site-packages\telegram\ext\_updater.py", line 688, in _network_loop_retry
2025-02-28 19:12:42,376 - root - INFO - [Telegram Bot] if not await action_cb():
2025-02-28 19:12:42,376 - root - INFO - [Telegram Bot] File "C:\Python310\lib\site-packages\telegram\ext\_updater.py", line 384, in polling_action_cb
2025-02-28 19:12:42,376 - root - INFO - [Telegram Bot] raise exc
2025-02-28 19:12:42,376 - root - INFO - [Telegram Bot] File "C:\Python310\lib\site-packages\telegram\ext\_updater.py", line 373, in polling_action_cb
2025-02-28 19:12:42,376 - root - INFO - [Telegram Bot] updates = await self.bot.get_updates(
2025-02-28 19:12:42,377 - root - INFO - [Telegram Bot] File "C:\Python310\lib\site-packages\telegram\ext\_extbot.py", line 558, in get_updates
2025-02-28 19:12:42,377 - root - INFO - [Telegram Bot] updates = await super().get_updates(
2025-02-28 19:12:42,377 - root - INFO - [Telegram Bot] File "C:\Python310\lib\site-packages\telegram\_bot.py", line 525, in decorator
2025-02-28 19:12:42,378 - root - INFO - [Telegram Bot] result = await func(self, *args, **kwargs)  # skipcq: PYL-E1102
2025-02-28 19:12:42,378 - root - INFO - [Telegram Bot] File "C:\Python310\lib\site-packages\telegram\_bot.py", line 3584, in get_updates
2025-02-28 19:12:42,378 - root - INFO - [Telegram Bot] await self._post(
2025-02-28 19:12:42,379 - root - INFO - [Telegram Bot] File "C:\Python310\lib\site-packages\telegram\_bot.py", line 613, in _post
2025-02-28 19:12:42,379 - root - INFO - [Telegram Bot] return await self._do_post(
2025-02-28 19:12:42,379 - root - INFO - [Telegram Bot] File "C:\Python310\lib\site-packages\telegram\ext\_extbot.py", line 340, in _do_post
2025-02-28 19:12:42,380 - root - INFO - [Telegram Bot] return await super()._do_post(
2025-02-28 19:12:42,380 - root - INFO - [Telegram Bot] File "C:\Python310\lib\site-packages\telegram\_bot.py", line 641, in _do_post
2025-02-28 19:12:42,380 - root - INFO - [Telegram Bot] return await request.post(
2025-02-28 19:12:42,381 - root - INFO - [Telegram Bot] File "C:\Python310\lib\site-packages\telegram\request\_baserequest.py", line 200, in post
2025-02-28 19:12:42,381 - root - INFO - [Telegram Bot] result = await self._request_wrapper(
2025-02-28 19:12:42,381 - root - INFO - [Telegram Bot] File "C:\Python310\lib\site-packages\telegram\request\_baserequest.py", line 381, in _request_wrapper
2025-02-28 19:12:42,381 - root - INFO - [Telegram Bot] raise Conflict(message)
2025-02-28 19:12:42,382 - root - INFO - [Telegram Bot] telegram.error.Conflict: Conflict: terminated by other getUpdates request; make sure that only one bot instance is running
2025-02-28 19:12:53,511 - root - INFO - [Telegram Bot] 2025-02-28 19:12:53,511 - httpx - INFO - HTTP Request: POST https://api.telegram.org/bot8068331897:AAHa8V519tgNs7vFSEs9OdAyykx8yWH-Xx0/getUpdates "HTTP/1.1 200 OK"
2025-02-28 19:13:03,628 - root - INFO - [Telegram Bot] 2025-02-28 19:13:03,628 - httpx - INFO - HTTP Request: POST https://api.telegram.org/bot8068331897:AAHa8V519tgNs7vFSEs9OdAyykx8yWH-Xx0/getUpdates "HTTP/1.1 200 OK"
2025-02-28 19:13:13,761 - root - INFO - [Telegram Bot] 2025-02-28 19:13:13,761 - httpx - INFO - HTTP Request: POST https://api.telegram.org/bot8068331897:AAHa8V519tgNs7vFSEs9OdAyykx8yWH-Xx0/getUpdates "HTTP/1.1 200 OK"
2025-02-28 19:13:17,053 - root - INFO - [Telegram Bot] 2025-02-28 19:13:17,053 - httpx - INFO - HTTP Request: POST https://api.telegram.org/bot8068331897:AAHa8V519tgNs7vFSEs9OdAyykx8yWH-Xx0/getUpdates "HTTP/1.1 409 Conflict"
2025-02-28 19:13:17,056 - root - INFO - [Telegram Bot] 2025-02-28 19:13:17,054 - telegram.ext.Updater - ERROR - Error while getting Updates: Conflict: terminated by other getUpdates request; make sure that only one bot instance is running
2025-02-28 19:13:17,057 - root - INFO - [Telegram Bot] 2025-02-28 19:13:17,056 - telegram.ext.Updater - ERROR - Exception happened while polling for updates.
2025-02-28 19:13:17,057 - root - INFO - [Telegram Bot] Traceback (most recent call last):
2025-02-28 19:13:17,057 - root - INFO - [Telegram Bot] File "C:\Python310\lib\site-packages\telegram\ext\_updater.py", line 688, in _network_loop_retry
2025-02-28 19:13:17,057 - root - INFO - [Telegram Bot] if not await action_cb():
2025-02-28 19:13:17,057 - root - INFO - [Telegram Bot] File "C:\Python310\lib\site-packages\telegram\ext\_updater.py", line 384, in polling_action_cb
2025-02-28 19:13:17,057 - root - INFO - [Telegram Bot] raise exc
2025-02-28 19:13:17,058 - root - INFO - [Telegram Bot] File "C:\Python310\lib\site-packages\telegram\ext\_updater.py", line 373, in polling_action_cb
2025-02-28 19:13:17,058 - root - INFO - [Telegram Bot] updates = await self.bot.get_updates(
2025-02-28 19:13:17,058 - root - INFO - [Telegram Bot] File "C:\Python310\lib\site-packages\telegram\ext\_extbot.py", line 558, in get_updates
2025-02-28 19:13:17,058 - root - INFO - [Telegram Bot] updates = await super().get_updates(
2025-02-28 19:13:17,058 - root - INFO - [Telegram Bot] File "C:\Python310\lib\site-packages\telegram\_bot.py", line 525, in decorator
2025-02-28 19:13:17,058 - root - INFO - [Telegram Bot] result = await func(self, *args, **kwargs)  # skipcq: PYL-E1102
2025-02-28 19:13:17,058 - root - INFO - [Telegram Bot] File "C:\Python310\lib\site-packages\telegram\_bot.py", line 3584, in get_updates
2025-02-28 19:13:17,059 - root - INFO - [Telegram Bot] await self._post(
2025-02-28 19:13:17,059 - root - INFO - [Telegram Bot] File "C:\Python310\lib\site-packages\telegram\_bot.py", line 613, in _post
2025-02-28 19:13:17,059 - root - INFO - [Telegram Bot] return await self._do_post(
2025-02-28 19:13:17,060 - root - INFO - [Telegram Bot] File "C:\Python310\lib\site-packages\telegram\ext\_extbot.py", line 340, in _do_post
2025-02-28 19:13:17,060 - root - INFO - [Telegram Bot] return await super()._do_post(
2025-02-28 19:13:17,060 - root - INFO - [Telegram Bot] File "C:\Python310\lib\site-packages\telegram\_bot.py", line 641, in _do_post
2025-02-28 19:13:17,060 - root - INFO - [Telegram Bot] return await request.post(
2025-02-28 19:13:17,060 - root - INFO - [Telegram Bot] File "C:\Python310\lib\site-packages\telegram\request\_baserequest.py", line 200, in post
2025-02-28 19:13:17,061 - root - INFO - [Telegram Bot] result = await self._request_wrapper(
2025-02-28 19:13:17,061 - root - INFO - [Telegram Bot] File "C:\Python310\lib\site-packages\telegram\request\_baserequest.py", line 381, in _request_wrapper
2025-02-28 19:13:17,061 - root - INFO - [Telegram Bot] raise Conflict(message)
2025-02-28 19:13:17,061 - root - INFO - [Telegram Bot] telegram.error.Conflict: Conflict: terminated by other getUpdates request; make sure that only one bot instance is running
2025-02-28 19:13:28,142 - root - INFO - [Telegram Bot] 2025-02-28 19:13:28,142 - httpx - INFO - HTTP Request: POST https://api.telegram.org/bot8068331897:AAHa8V519tgNs7vFSEs9OdAyykx8yWH-Xx0/getUpdates "HTTP/1.1 200 OK"
2025-02-28 19:13:38,304 - root - INFO - [Telegram Bot] 2025-02-28 19:13:38,304 - httpx - INFO - HTTP Request: POST https://api.telegram.org/bot8068331897:AAHa8V519tgNs7vFSEs9OdAyykx8yWH-Xx0/getUpdates "HTTP/1.1 200 OK"
2025-02-28 19:13:48,435 - root - INFO - [Telegram Bot] 2025-02-28 19:13:48,435 - httpx - INFO - HTTP Request: POST https://api.telegram.org/bot8068331897:AAHa8V519tgNs7vFSEs9OdAyykx8yWH-Xx0/getUpdates "HTTP/1.1 200 OK"
2025-02-28 19:13:51,684 - root - INFO - [Telegram Bot] 2025-02-28 19:13:51,683 - httpx - INFO - HTTP Request: POST https://api.telegram.org/bot8068331897:AAHa8V519tgNs7vFSEs9OdAyykx8yWH-Xx0/getUpdates "HTTP/1.1 409 Conflict"
2025-02-28 19:13:51,686 - root - INFO - [Telegram Bot] 2025-02-28 19:13:51,685 - telegram.ext.Updater - ERROR - Error while getting Updates: Conflict: terminated by other getUpdates request; make sure that only one bot instance is running
2025-02-28 19:13:51,688 - root - INFO - [Telegram Bot] 2025-02-28 19:13:51,686 - telegram.ext.Updater - ERROR - Exception happened while polling for updates.
2025-02-28 19:13:51,690 - root - INFO - [Telegram Bot] Traceback (most recent call last):
2025-02-28 19:13:51,691 - root - INFO - [Telegram Bot] File "C:\Python310\lib\site-packages\telegram\ext\_updater.py", line 688, in _network_loop_retry
2025-02-28 19:13:51,692 - root - INFO - [Telegram Bot] if not await action_cb():
2025-02-28 19:13:51,692 - root - INFO - [Telegram Bot] File "C:\Python310\lib\site-packages\telegram\ext\_updater.py", line 384, in polling_action_cb
2025-02-28 19:13:51,694 - root - INFO - [Telegram Bot] raise exc
2025-02-28 19:13:51,694 - root - INFO - [Telegram Bot] File "C:\Python310\lib\site-packages\telegram\ext\_updater.py", line 373, in polling_action_cb
2025-02-28 19:13:51,696 - root - INFO - [Telegram Bot] updates = await self.bot.get_updates(
2025-02-28 19:13:51,697 - root - INFO - [Telegram Bot] File "C:\Python310\lib\site-packages\telegram\ext\_extbot.py", line 558, in get_updates
2025-02-28 19:13:51,698 - root - INFO - [Telegram Bot] updates = await super().get_updates(
2025-02-28 19:13:51,698 - root - INFO - [Telegram Bot] File "C:\Python310\lib\site-packages\telegram\_bot.py", line 525, in decorator
